ERROR:root:Unable to insert into db
Traceback (most recent call last):
  File "/home/willy/Development/reddit-groupme-bot/src/database_client.py", line 22, in insertSubmission
    id = submissions_collection.insert_one(submission)
  File "/home/willy/anaconda3/lib/python3.6/site-packages/pymongo/collection.py", line 684, in insert_one
    common.validate_is_document_type("document", document)
  File "/home/willy/anaconda3/lib/python3.6/site-packages/pymongo/common.py", line 453, in validate_is_document_type
    "collections.MutableMapping" % (option,))
TypeError: document must be an instance of dict, bson.son.SON, bson.raw_bson.RawBSONDocument, or a type that inherits from collections.MutableMapping
ERROR:root:Could not instantiate clients.
Traceback (most recent call last):
  File "/home/willy/Development/reddit-groupme-bot/src/app.py", line 36, in _instantiate_clients
    if reddit == None:
UnboundLocalError: local variable 'reddit' referenced before assignment
ERROR:root:Error trying to connect to reddit
Traceback (most recent call last):
  File "src/scheduler.py", line 10, in main
    start()
  File "/home/willy/Development/reddit-groupme-bot/src/app.py", line 17, in start
    hot_subs = reddit.get_hot_submissions()
AttributeError: 'NoneType' object has no attribute 'get_hot_submissions'
ERROR:root:Bringing the bot down for a couple hours
ERROR:root:Could not instantiate clients.
Traceback (most recent call last):
  File "/home/willy/Development/reddit-groupme-bot/src/app.py", line 36, in _instantiate_clients
    if reddit == None:
UnboundLocalError: local variable 'reddit' referenced before assignment
ERROR:root:Error trying to connect to reddit
Traceback (most recent call last):
  File "src/scheduler.py", line 10, in main
    start()
  File "/home/willy/Development/reddit-groupme-bot/src/app.py", line 17, in start
    hot_subs = reddit.get_hot_submissions()
AttributeError: 'NoneType' object has no attribute 'get_hot_submissions'
ERROR:root:Bringing the bot down for a couple hours
ERROR:root:Could not instantiate clients.
Traceback (most recent call last):
  File "/home/willy/Development/reddit-groupme-bot/src/app.py", line 36, in _instantiate_clients
    if reddit == None:
UnboundLocalError: local variable 'reddit' referenced before assignment
ERROR:root:Error trying to connect to reddit
Traceback (most recent call last):
  File "src/scheduler.py", line 10, in main
    start()
  File "/home/willy/Development/reddit-groupme-bot/src/app.py", line 17, in start
    hot_subs = reddit.get_hot_submissions()
AttributeError: 'NoneType' object has no attribute 'get_hot_submissions'
ERROR:root:Bringing the bot down for a couple hours
ERROR:root:Could not instantiate clients.
Traceback (most recent call last):
  File "/home/willy/Development/reddit-groupme-bot/src/app.py", line 36, in _instantiate_clients
    if reddit is None:
UnboundLocalError: local variable 'reddit' referenced before assignment
ERROR:root:Error trying to connect to reddit
Traceback (most recent call last):
  File "src/scheduler.py", line 10, in main
    start()
  File "/home/willy/Development/reddit-groupme-bot/src/app.py", line 17, in start
    hot_subs = reddit.get_hot_submissions()
AttributeError: 'NoneType' object has no attribute 'get_hot_submissions'
ERROR:root:Bringing the bot down for a couple hours
ERROR:root:Error trying to connect to reddit
Traceback (most recent call last):
  File "src/scheduler.py", line 10, in main
    start()
  File "/home/willy/Development/reddit-groupme-bot/src/app.py", line 18, in start
    hot_subs = reddit.get_hot_submissions()
AttributeError: 'NoneType' object has no attribute 'get_hot_submissions'
ERROR:root:Bringing the bot down for a couple hours
ERROR:root:Error trying to connect to reddit
Traceback (most recent call last):
  File "src/scheduler.py", line 10, in main
    start()
  File "/home/willy/Development/reddit-groupme-bot/src/app.py", line 18, in start
    hot_subs = reddit.get_hot_submissions()
AttributeError: 'NoneType' object has no attribute 'get_hot_submissions'
ERROR:root:Bringing the bot down for a couple hours
ERROR:root:Error trying to connect to reddit
Traceback (most recent call last):
  File "src/scheduler.py", line 10, in main
    start()
  File "/home/willy/Development/reddit-groupme-bot/src/app.py", line 20, in start
    hot_subs = reddit.get_hot_submissions()
  File "/home/willy/Development/reddit-groupme-bot/src/app.py", line 20, in start
    hot_subs = reddit.get_hot_submissions()
  File "/home/willy/anaconda3/lib/python3.6/bdb.py", line 48, in trace_dispatch
    return self.dispatch_line(frame)
  File "/home/willy/anaconda3/lib/python3.6/bdb.py", line 67, in dispatch_line
    if self.quitting: raise BdbQuit
bdb.BdbQuit
ERROR:root:Bringing the bot down for a couple hours
ERROR:root:Error trying to connect to reddit
Traceback (most recent call last):
  File "src/scheduler.py", line 10, in main
    start()
  File "/home/willy/Development/reddit-groupme-bot/src/app.py", line 20, in start
    hot_subs = reddit.get_hot_submissions()
  File "/home/willy/Development/reddit-groupme-bot/src/app.py", line 31, in _remove_duplicates
    if submission['id'] not in deque:
TypeError: argument of type 'type' is not iterable
ERROR:root:Bringing the bot down for a couple hours
ERROR:root:Error trying to connect to reddit
Traceback (most recent call last):
  File "src/scheduler.py", line 10, in main
    start()
  File "/home/willy/Development/reddit-groupme-bot/src/app.py", line 20, in start
    new_subs = _remove_duplicates(hot_subs)
  File "/home/willy/Development/reddit-groupme-bot/src/app.py", line 31, in _remove_duplicates
    if submission['id'] not in deque:
  File "/home/willy/Development/reddit-groupme-bot/src/app.py", line 31, in _remove_duplicates
    if submission['id'] not in deque:
  File "/home/willy/anaconda3/lib/python3.6/bdb.py", line 48, in trace_dispatch
    return self.dispatch_line(frame)
  File "/home/willy/anaconda3/lib/python3.6/bdb.py", line 67, in dispatch_line
    if self.quitting: raise BdbQuit
bdb.BdbQuit
ERROR:root:Bringing the bot down for a couple hours
ERROR:root:Error trying to connect to reddit
Traceback (most recent call last):
  File "src/scheduler.py", line 10, in main
    start()
  File "/home/willy/Development/reddit-groupme-bot/src/app.py", line 21, in start
    new_subs = _remove_duplicates(hot_subs)
  File "/home/willy/Development/reddit-groupme-bot/src/app.py", line 33, in _remove_duplicates
    if submission['id'] not in queue:
NameError: name 'queue' is not defined
ERROR:root:Bringing the bot down for a couple hours
ERROR:root:Error trying to connect to reddit
Traceback (most recent call last):
  File "src/scheduler.py", line 10, in main
    start()
  File "/home/willy/Development/reddit-groupme-bot/src/app.py", line 25, in start
    groupme_client.post_message(sub.title)
AttributeError: 'NoneType' object has no attribute 'post_message'
ERROR:root:Bringing the bot down for a couple hours
ERROR:root:Error trying to connect to reddit
Traceback (most recent call last):
  File "src/scheduler.py", line 10, in main
    start()
  File "/home/willy/Development/reddit-groupme-bot/src/app.py", line 26, in start
    groupme_client.post_text_message(sub.title)
AttributeError: 'Submission' object has no attribute 'title'
ERROR:root:Bringing the bot down for a couple hours
ERROR:root:Error trying to connect to reddit
Traceback (most recent call last):
  File "src/scheduler.py", line 10, in main
    start()
  File "/home/willy/Development/reddit-groupme-bot/src/app.py", line 24, in start
    print("inserting submissions")
  File "/home/willy/Development/reddit-groupme-bot/src/app.py", line 24, in start
    print("inserting submissions")
  File "/home/willy/anaconda3/lib/python3.6/bdb.py", line 48, in trace_dispatch
    return self.dispatch_line(frame)
  File "/home/willy/anaconda3/lib/python3.6/bdb.py", line 67, in dispatch_line
    if self.quitting: raise BdbQuit
bdb.BdbQuit
ERROR:root:Bringing the bot down for a couple hours
ERROR:root:Unable to get submissions
Traceback (most recent call last):
  File "/home/willy/anaconda3/lib/python3.6/site-packages/prawcore/requestor.py", line 47, in request
    return self._http.request(*args, timeout=TIMEOUT, **kwargs)
  File "/home/willy/anaconda3/lib/python3.6/site-packages/requests/sessions.py", line 508, in request
    resp = self.send(prep, **send_kwargs)
  File "/home/willy/anaconda3/lib/python3.6/site-packages/requests/sessions.py", line 618, in send
    r = adapter.send(request, **kwargs)
  File "/home/willy/anaconda3/lib/python3.6/site-packages/requests/adapters.py", line 440, in send
    timeout=timeout
  File "/home/willy/anaconda3/lib/python3.6/site-packages/urllib3/connectionpool.py", line 601, in urlopen
    chunked=chunked)
  File "/home/willy/anaconda3/lib/python3.6/site-packages/urllib3/connectionpool.py", line 383, in _make_request
    httplib_response = conn.getresponse()
  File "<string>", line 2, in raise_from
  File "/home/willy/anaconda3/lib/python3.6/site-packages/urllib3/connectionpool.py", line 383, in _make_request
    httplib_response = conn.getresponse()
  File "/home/willy/anaconda3/lib/python3.6/http/client.py", line 1331, in getresponse
    response.begin()
  File "/home/willy/anaconda3/lib/python3.6/http/client.py", line 297, in begin
    version, status, reason = self._read_status()
  File "/home/willy/anaconda3/lib/python3.6/http/client.py", line 258, in _read_status
    line = str(self.fp.readline(_MAXLINE + 1), "iso-8859-1")
  File "/home/willy/anaconda3/lib/python3.6/socket.py", line 586, in readinto
    return self._sock.recv_into(b)
  File "/home/willy/anaconda3/lib/python3.6/site-packages/urllib3/contrib/pyopenssl.py", line 292, in recv_into
    rd = util.wait_for_read(self.socket, self.socket.gettimeout())
  File "/home/willy/anaconda3/lib/python3.6/site-packages/urllib3/util/wait.py", line 33, in wait_for_read
    return _wait_for_io_events(socks, EVENT_READ, timeout)
  File "/home/willy/anaconda3/lib/python3.6/site-packages/urllib3/util/wait.py", line 26, in _wait_for_io_events
    selector.select(timeout) if key[1] & events]
  File "/home/willy/anaconda3/lib/python3.6/site-packages/urllib3/util/selectors.py", line 438, in select
    maxevents=max_events)
  File "/home/willy/anaconda3/lib/python3.6/site-packages/urllib3/util/selectors.py", line 64, in _syscall_wrapper
    return func(*args, **kwargs)
  File "/home/willy/anaconda3/lib/python3.6/bdb.py", line 52, in trace_dispatch
    return self.dispatch_return(frame, arg)
  File "/home/willy/anaconda3/lib/python3.6/bdb.py", line 96, in dispatch_return
    if self.quitting: raise BdbQuit
bdb.BdbQuit

During handling of the above exception, another exception occurred:

Traceback (most recent call last):
  File "/home/willy/Development/reddit-groupme-bot/src/reddit_client.py", line 28, in get_hot_submissions
    for submission in self.reddit.subreddit('soccer').hot(limit=25):
  File "/home/willy/anaconda3/lib/python3.6/site-packages/praw/models/listing/generator.py", line 52, in __next__
    self._next_batch()
  File "/home/willy/anaconda3/lib/python3.6/site-packages/praw/models/listing/generator.py", line 62, in _next_batch
    self._listing = self._reddit.get(self.url, params=self.params)
  File "/home/willy/anaconda3/lib/python3.6/site-packages/praw/reddit.py", line 371, in get
    data = self.request('GET', path, params=params)
  File "/home/willy/anaconda3/lib/python3.6/site-packages/praw/reddit.py", line 486, in request
    params=params)
  File "/home/willy/anaconda3/lib/python3.6/site-packages/prawcore/sessions.py", line 182, in request
    params=params, url=url)
  File "/home/willy/anaconda3/lib/python3.6/site-packages/prawcore/sessions.py", line 113, in _request_with_retries
    data, files, json, method, params, retries, url)
  File "/home/willy/anaconda3/lib/python3.6/site-packages/prawcore/sessions.py", line 98, in _make_request
    params=params)
  File "/home/willy/anaconda3/lib/python3.6/site-packages/prawcore/rate_limit.py", line 33, in call
    response = request_function(*args, **kwargs)
  File "/home/willy/anaconda3/lib/python3.6/site-packages/prawcore/requestor.py", line 47, in request
    return self._http.request(*args, timeout=TIMEOUT, **kwargs)
prawcore.exceptions.RequestException: error with request 
ERROR:root:Error trying to connect to reddit
Traceback (most recent call last):
  File "src/scheduler.py", line 10, in main
    start()
  File "/home/willy/Development/reddit-groupme-bot/src/app.py", line 24, in start
    print("inserting submissions")
  File "/home/willy/Development/reddit-groupme-bot/src/app.py", line 33, in _remove_duplicates
    for submission in submissions:
TypeError: 'NoneType' object is not iterable
ERROR:root:Bringing the bot down for a couple hours
